Workbook

Sheet 1ST
A1: REGISTRATION | B1: CALLSIGN | C1: ACFT TYPE | D1: FLIGHT TYPE | E1: FLIGHT RULES | F1: DEP POINT | G1: DEP TIME | H1: ARR POINT | I1: ARR TIME | J1: WTC D | K1: WTC A | L1: T&G | M1: O/S | N1: FIS | O1: CAPTAIN | P1: POB | Q1: REMARKS | R1: EGOW Code | S1: Unit Code | T1: Movement Number | U1: T&G Dupliction
B2: =IF(ISERROR(VLOOKUP(A2,'Registration Database'!A:N,13,0)),"",VLOOKUP(A2,'Registration Database'!A:N,13,0)) | C2: =IF(ISERROR(VLOOKUP(A2,'Registration Database'!A:E,3,0))," ",VLOOKUP(A2,'Registration Database'!A:E,3,0)) | D2: =IF(ISNUMBER(SEARCH("UAM", B2)), "LOC", "") | E2: =IF(OR(D2="LOC", D2="OVR"), "V", "") | F2: =IF(OR(D2="DEP",D2="LOC"),"EGOW","") | H2: =IF(OR(D2="ARR",D2="LOC"),"EGOW","") | J2: =IF(ISERROR(VLOOKUP(C2,'WTC Database'!C:G,4,0))," ",VLOOKUP(C2,'WTC Database'!C:G,4,0)) | K2: =IF(ISERROR(VLOOKUP(C2,'WTC Database'!C:G,5,0))," ",VLOOKUP(C2,'WTC Database'!C:G,5,0)) | N2: =IF(D2="OVR",1,0) -> 0 | O2: =IF(ISERROR(VLOOKUP(B2,'Callsign Database'!A:F,4,0))," ",VLOOKUP(B2,'Callsign Database'!A:F,4,0)) | Q2: =IF(ISERROR(VLOOKUP(A2,'Registration Database'!A:O,15,0))," ",VLOOKUP(A2,'Registration Database'!A:O,15,0)) | R2: =IF(ISERROR(VLOOKUP(A2,'Registration Database'!A:F,6,0))," ",VLOOKUP(A2,'Registration Database'!A:F,6,0)) | S2: =IF(ISERROR(VLOOKUP(B2,'Callsign Database'!A:F,3,0)),"",VLOOKUP(B2,'Callsign Database'!A:F,3,0)) | T2: =IF(D2="loc",2)+IF(OR(D2="DEP",D2="ARR"),"1")+IF(D2="ovr","0") -> 0 | U2: =L2*2 -> 0
B3: =IF(ISERROR(VLOOKUP(A3,'Registration Database'!A:N,13,0)),"",VLOOKUP(A3,'Registration Database'!A:N,13,0)) | C3: =IF(ISERROR(VLOOKUP(A3,'Registration Database'!A:E,3,0))," ",VLOOKUP(A3,'Registration Database'!A:E,3,0)) | D3: =IF(ISNUMBER(SEARCH("UAM", B3)), "LOC", "") | E3: =IF(OR(D3="LOC", D3="OVR"), "V", "") | F3: =IF(OR(D3="DEP",D3="LOC"),"EGOW","") | H3: =IF(OR(D3="ARR",D3="LOC"),"EGOW","") | J3: =IF(ISERROR(VLOOKUP(C3,'WTC Database'!C:G,4,0))," ",VLOOKUP(C3,'WTC Database'!C:G,4,0)) | K3: =IF(ISERROR(VLOOKUP(C3,'WTC Database'!C:G,5,0))," ",VLOOKUP(C3,'WTC Database'!C:G,5,0)) | N3: =IF(D3="OVR",1,0) -> 0 | O3: =IF(ISERROR(VLOOKUP(B3,'Callsign Database'!A:F,4,0))," ",VLOOKUP(B3,'Callsign Database'!A:F,4,0)) | Q3: =IF(ISERROR(VLOOKUP(A3,'Registration Database'!A:O,15,0))," ",VLOOKUP(A3,'Registration Database'!A:O,15,0)) | R3: =IF(ISERROR(VLOOKUP(A3,'Registration Database'!A:F,6,0))," ",VLOOKUP(A3,'Registration Database'!A:F,6,0)) | S3: =IF(ISERROR(VLOOKUP(B3,'Callsign Database'!A:F,3,0)),"",VLOOKUP(B3,'Callsign Database'!A:F,3,0)) | T3: =IF(D3="loc",2)+IF(OR(D3="DEP",D3="ARR"),"1")+IF(D3="ovr","0") -> 0 | U3: =L3*2 -> 0
B4: =IF(ISERROR(VLOOKUP(A4,'Registration Database'!A:N,13,0)),"",VLOOKUP(A4,'Registration Database'!A:N,13,0)) | C4: =IF(ISERROR(VLOOKUP(A4,'Registration Database'!A:E,3,0))," ",VLOOKUP(A4,'Registration Database'!A:E,3,0)) | D4: =IF(ISNUMBER(SEARCH("UAM", B4)), "LOC", "") | E4: =IF(OR(D4="LOC", D4="OVR"), "V", "") | F4: =IF(OR(D4="DEP",D4="LOC"),"EGOW","") | H4: =IF(OR(D4="ARR",D4="LOC"),"EGOW","") | J4: =IF(ISERROR(VLOOKUP(C4,'WTC Database'!C:G,4,0))," ",VLOOKUP(C4,'WTC Database'!C:G,4,0)) | K4: =IF(ISERROR(VLOOKUP(C4,'WTC Database'!C:G,5,0))," ",VLOOKUP(C4,'WTC Database'!C:G,5,0)) | N4: =IF(D4="OVR",1,0) -> 0 | O4: =IF(ISERROR(VLOOKUP(B4,'Callsign Database'!A:F,4,0))," ",VLOOKUP(B4,'Callsign Database'!A:F,4,0)) | Q4: =IF(ISERROR(VLOOKUP(A4,'Registration Database'!A:O,15,0))," ",VLOOKUP(A4,'Registration Database'!A:O,15,0)) | R4: =IF(ISERROR(VLOOKUP(A4,'Registration Database'!A:F,6,0))," ",VLOOKUP(A4,'Registration Database'!A:F,6,0)) | S4: =IF(ISERROR(VLOOKUP(B4,'Callsign Database'!A:F,3,0)),"",VLOOKUP(B4,'Callsign Database'!A:F,3,0)) | T4: =IF(D4="loc",2)+IF(OR(D4="DEP",D4="ARR"),"1")+IF(D4="ovr","0") -> 0 | U4: =L4*2 -> 0
B5: =IF(ISERROR(VLOOKUP(A5,'Registration Database'!A:N,13,0)),"",VLOOKUP(A5,'Registration Database'!A:N,13,0)) | C5: =IF(ISERROR(VLOOKUP(A5,'Registration Database'!A:E,3,0))," ",VLOOKUP(A5,'Registration Database'!A:E,3,0)) | D5: =IF(ISNUMBER(SEARCH("UAM", B5)), "LOC", "") | E5: =IF(OR(D5="LOC", D5="OVR"), "V", "") | F5: =IF(OR(D5="DEP",D5="LOC"),"EGOW","") | H5: =IF(OR(D5="ARR",D5="LOC"),"EGOW","") | J5: =IF(ISERROR(VLOOKUP(C5,'WTC Database'!C:G,4,0))," ",VLOOKUP(C5,'WTC Database'!C:G,4,0)) | K5: =IF(ISERROR(VLOOKUP(C5,'WTC Database'!C:G,5,0))," ",VLOOKUP(C5,'WTC Database'!C:G,5,0)) | N5: =IF(D5="OVR",1,0) -> 0 | O5: =IF(ISERROR(VLOOKUP(B5,'Callsign Database'!A:F,4,0))," ",VLOOKUP(B5,'Callsign Database'!A:F,4,0)) | Q5: =IF(ISERROR(VLOOKUP(A5,'Registration Database'!A:O,15,0))," ",VLOOKUP(A5,'Registration Database'!A:O,15,0)) | R5: =IF(ISERROR(VLOOKUP(A5,'Registration Database'!A:F,6,0))," ",VLOOKUP(A5,'Registration Database'!A:F,6,0)) | S5: =IF(ISERROR(VLOOKUP(B5,'Callsign Database'!A:F,3,0)),"",VLOOKUP(B5,'Callsign Database'!A:F,3,0)) | T5: =IF(D5="loc",2)+IF(OR(D5="DEP",D5="ARR"),"1")+IF(D5="ovr","0") -> 0 | U5: =L5*2 -> 0
B6: =IF(ISERROR(VLOOKUP(A6,'Registration Database'!A:N,13,0)),"",VLOOKUP(A6,'Registration Database'!A:N,13,0)) | C6: =IF(ISERROR(VLOOKUP(A6,'Registration Database'!A:E,3,0))," ",VLOOKUP(A6,'Registration Database'!A:E,3,0)) | D6: =IF(ISNUMBER(SEARCH("UAM", B6)), "LOC", "") | E6: =IF(OR(D6="LOC", D6="OVR"), "V", "") | F6: =IF(OR(D6="DEP",D6="LOC"),"EGOW","") | H6: =IF(OR(D6="ARR",D6="LOC"),"EGOW","") | J6: =IF(ISERROR(VLOOKUP(C6,'WTC Database'!C:G,4,0))," ",VLOOKUP(C6,'WTC Database'!C:G,4,0)) | K6: =IF(ISERROR(VLOOKUP(C6,'WTC Database'!C:G,5,0))," ",VLOOKUP(C6,'WTC Database'!C:G,5,0)) | N6: =IF(D6="OVR",1,0) -> 0 | O6: =IF(ISERROR(VLOOKUP(B6,'Callsign Database'!A:F,4,0))," ",VLOOKUP(B6,'Callsign Database'!A:F,4,0)) | Q6: =IF(ISERROR(VLOOKUP(A6,'Registration Database'!A:O,15,0))," ",VLOOKUP(A6,'Registration Database'!A:O,15,0)) | R6: =IF(ISERROR(VLOOKUP(A6,'Registration Database'!A:F,6,0))," ",VLOOKUP(A6,'Registration Database'!A:F,6,0)) | S6: =IF(ISERROR(VLOOKUP(B6,'Callsign Database'!A:F,3,0)),"",VLOOKUP(B6,'Callsign Database'!A:F,3,0)) | T6: =IF(D6="loc",2)+IF(OR(D6="DEP",D6="ARR"),"1")+IF(D6="ovr","0") -> 0 | U6: =L6*2 -> 0
B7: =IF(ISERROR(VLOOKUP(A7,'Registration Database'!A:N,13,0)),"",VLOOKUP(A7,'Registration Database'!A:N,13,0)) | C7: =IF(ISERROR(VLOOKUP(A7,'Registration Database'!A:E,3,0))," ",VLOOKUP(A7,'Registration Database'!A:E,3,0)) | D7: =IF(ISNUMBER(SEARCH("UAM", B7)), "LOC", "") | E7: =IF(OR(D7="LOC", D7="OVR"), "V", "") | F7: =IF(OR(D7="DEP",D7="LOC"),"EGOW","") | H7: =IF(OR(D7="ARR",D7="LOC"),"EGOW","") | J7: =IF(ISERROR(VLOOKUP(C7,'WTC Database'!C:G,4,0))," ",VLOOKUP(C7,'WTC Database'!C:G,4,0)) | K7: =IF(ISERROR(VLOOKUP(C7,'WTC Database'!C:G,5,0))," ",VLOOKUP(C7,'WTC Database'!C:G,5,0)) | N7: =IF(D7="OVR",1,0) -> 0 | O7: =IF(ISERROR(VLOOKUP(B7,'Callsign Database'!A:F,4,0))," ",VLOOKUP(B7,'Callsign Database'!A:F,4,0)) | Q7: =IF(ISERROR(VLOOKUP(A7,'Registration Database'!A:O,15,0))," ",VLOOKUP(A7,'Registration Database'!A:O,15,0)) | R7: =IF(ISERROR(VLOOKUP(A7,'Registration Database'!A:F,6,0))," ",VLOOKUP(A7,'Registration Database'!A:F,6,0)) | S7: =IF(ISERROR(VLOOKUP(B7,'Callsign Database'!A:F,3,0)),"",VLOOKUP(B7,'Callsign Database'!A:F,3,0)) | T7: =IF(D7="loc",2)+IF(OR(D7="DEP",D7="ARR"),"1")+IF(D7="ovr","0") -> 0 | U7: =L7*2 -> 0
B8: =IF(ISERROR(VLOOKUP(A8,'Registration Database'!A:N,13,0)),"",VLOOKUP(A8,'Registration Database'!A:N,13,0)) | C8: =IF(ISERROR(VLOOKUP(A8,'Registration Database'!A:E,3,0))," ",VLOOKUP(A8,'Registration Database'!A:E,3,0)) | D8: =IF(ISNUMBER(SEARCH("UAM", B8)), "LOC", "") | E8: =IF(OR(D8="LOC", D8="OVR"), "V", "") | F8: =IF(OR(D8="DEP",D8="LOC"),"EGOW","") | H8: =IF(OR(D8="ARR",D8="LOC"),"EGOW","") | J8: =IF(ISERROR(VLOOKUP(C8,'WTC Database'!C:G,4,0))," ",VLOOKUP(C8,'WTC Database'!C:G,4,0)) | K8: =IF(ISERROR(VLOOKUP(C8,'WTC Database'!C:G,5,0))," ",VLOOKUP(C8,'WTC Database'!C:G,5,0)) | N8: =IF(D8="OVR",1,0) -> 0 | O8: =IF(ISERROR(VLOOKUP(B8,'Callsign Database'!A:F,4,0))," ",VLOOKUP(B8,'Callsign Database'!A:F,4,0)) | Q8: =IF(ISERROR(VLOOKUP(A8,'Registration Database'!A:O,15,0))," ",VLOOKUP(A8,'Registration Database'!A:O,15,0)) | R8: =IF(ISERROR(VLOOKUP(A8,'Registration Database'!A:F,6,0))," ",VLOOKUP(A8,'Registration Database'!A:F,6,0)) | S8: =IF(ISERROR(VLOOKUP(B8,'Callsign Database'!A:F,3,0)),"",VLOOKUP(B8,'Callsign Database'!A:F,3,0)) | T8: =IF(D8="loc",2)+IF(OR(D8="DEP",D8="ARR"),"1")+IF(D8="ovr","0") -> 0 | U8: =L8*2 -> 0
B9: =IF(ISERROR(VLOOKUP(A9,'Registration Database'!A:N,13,0)),"",VLOOKUP(A9,'Registration Database'!A:N,13,0)) | C9: =IF(ISERROR(VLOOKUP(A9,'Registration Database'!A:E,3,0))," ",VLOOKUP(A9,'Registration Database'!A:E,3,0)) | D9: =IF(ISNUMBER(SEARCH("UAM", B9)), "LOC", "") | E9: =IF(OR(D9="LOC", D9="OVR"), "V", "") | F9: =IF(OR(D9="DEP",D9="LOC"),"EGOW","") | H9: =IF(OR(D9="ARR",D9="LOC"),"EGOW","") | J9: =IF(ISERROR(VLOOKUP(C9,'WTC Database'!C:G,4,0))," ",VLOOKUP(C9,'WTC Database'!C:G,4,0)) | K9: =IF(ISERROR(VLOOKUP(C9,'WTC Database'!C:G,5,0))," ",VLOOKUP(C9,'WTC Database'!C:G,5,0)) | N9: =IF(D9="OVR",1,0) -> 0 | O9: =IF(ISERROR(VLOOKUP(B9,'Callsign Database'!A:F,4,0))," ",VLOOKUP(B9,'Callsign Database'!A:F,4,0)) | Q9: =IF(ISERROR(VLOOKUP(A9,'Registration Database'!A:O,15,0))," ",VLOOKUP(A9,'Registration Database'!A:O,15,0)) | R9: =IF(ISERROR(VLOOKUP(A9,'Registration Database'!A:F,6,0))," ",VLOOKUP(A9,'Registration Database'!A:F,6,0)) | S9: =IF(ISERROR(VLOOKUP(B9,'Callsign Database'!A:F,3,0)),"",VLOOKUP(B9,'Callsign Database'!A:F,3,0)) | T9: =IF(D9="loc",2)+IF(OR(D9="DEP",D9="ARR"),"1")+IF(D9="ovr","0") -> 0 | U9: =L9*2 -> 0
B10: =IF(ISERROR(VLOOKUP(A10,'Registration Database'!A:N,13,0)),"",VLOOKUP(A10,'Registration Database'!A:N,13,0)) | C10: =IF(ISERROR(VLOOKUP(A10,'Registration Database'!A:E,3,0))," ",VLOOKUP(A10,'Registration Database'!A:E,3,0)) | D10: =IF(ISNUMBER(SEARCH("UAM", B10)), "LOC", "") | E10: =IF(OR(D10="LOC", D10="OVR"), "V", "") | F10: =IF(OR(D10="DEP",D10="LOC"),"EGOW","") | H10: =IF(OR(D10="ARR",D10="LOC"),"EGOW","") | J10: =IF(ISERROR(VLOOKUP(C10,'WTC Database'!C:G,4,0))," ",VLOOKUP(C10,'WTC Database'!C:G,4,0)) | K10: =IF(ISERROR(VLOOKUP(C10,'WTC Database'!C:G,5,0))," ",VLOOKUP(C10,'WTC Database'!C:G,5,0)) | N10: =IF(D10="OVR",1,0) -> 0 | O10: =IF(ISERROR(VLOOKUP(B10,'Callsign Database'!A:F,4,0))," ",VLOOKUP(B10,'Callsign Database'!A:F,4,0)) | Q10: =IF(ISERROR(VLOOKUP(A10,'Registration Database'!A:O,15,0))," ",VLOOKUP(A10,'Registration Database'!A:O,15,0)) | R10: =IF(ISERROR(VLOOKUP(A10,'Registration Database'!A:F,6,0))," ",VLOOKUP(A10,'Registration Database'!A:F,6,0)) | S10: =IF(ISERROR(VLOOKUP(B10,'Callsign Database'!A:F,3,0)),"",VLOOKUP(B10,'Callsign Database'!A:F,3,0)) | T10: =IF(D10="loc",2)+IF(OR(D10="DEP",D10="ARR"),"1")+IF(D10="ovr","0") -> 0 | U10: =L10*2 -> 0
B11: =IF(ISERROR(VLOOKUP(A11,'Registration Database'!A:N,13,0)),"",VLOOKUP(A11,'Registration Database'!A:N,13,0)) | C11: =IF(ISERROR(VLOOKUP(A11,'Registration Database'!A:E,3,0))," ",VLOOKUP(A11,'Registration Database'!A:E,3,0)) | D11: =IF(ISNUMBER(SEARCH("UAM", B11)), "LOC", "") | E11: =IF(OR(D11="LOC", D11="OVR"), "V", "") | F11: =IF(OR(D11="DEP",D11="LOC"),"EGOW","") | H11: =IF(OR(D11="ARR",D11="LOC"),"EGOW","") | J11: =IF(ISERROR(VLOOKUP(C11,'WTC Database'!C:G,4,0))," ",VLOOKUP(C11,'WTC Database'!C:G,4,0)) | K11: =IF(ISERROR(VLOOKUP(C11,'WTC Database'!C:G,5,0))," ",VLOOKUP(C11,'WTC Database'!C:G,5,0)) | N11: =IF(D11="OVR",1,0) -> 0 | O11: =IF(ISERROR(VLOOKUP(B11,'Callsign Database'!A:F,4,0))," ",VLOOKUP(B11,'Callsign Database'!A:F,4,0)) | Q11: =IF(ISERROR(VLOOKUP(A11,'Registration Database'!A:O,15,0))," ",VLOOKUP(A11,'Registration Database'!A:O,15,0)) | R11: =IF(ISERROR(VLOOKUP(A11,'Registration Database'!A:F,6,0))," ",VLOOKUP(A11,'Registration Database'!A:F,6,0)) | S11: =IF(ISERROR(VLOOKUP(B11,'Callsign Database'!A:F,3,0)),"",VLOOKUP(B11,'Callsign Database'!A:F,3,0)) | T11: =IF(D11="loc",2)+IF(OR(D11="DEP",D11="ARR"),"1")+IF(D11="ovr","0") -> 0 | U11: =L11*2 -> 0
B12: =IF(ISERROR(VLOOKUP(A12,'Registration Database'!A:N,13,0)),"",VLOOKUP(A12,'Registration Database'!A:N,13,0)) | C12: =IF(ISERROR(VLOOKUP(A12,'Registration Database'!A:E,3,0))," ",VLOOKUP(A12,'Registration Database'!A:E,3,0)) | D12: =IF(ISNUMBER(SEARCH("UAM", B12)), "LOC", "") | E12: =IF(OR(D12="LOC", D12="OVR"), "V", "") | F12: =IF(OR(D12="DEP",D12="LOC"),"EGOW","") | H12: =IF(OR(D12="ARR",D12="LOC"),"EGOW","") | J12: =IF(ISERROR(VLOOKUP(C12,'WTC Database'!C:G,4,0))," ",VLOOKUP(C12,'WTC Database'!C:G,4,0)) | K12: =IF(ISERROR(VLOOKUP(C12,'WTC Database'!C:G,5,0))," ",VLOOKUP(C12,'WTC Database'!C:G,5,0)) | N12: =IF(D12="OVR",1,0) -> 0 | O12: =IF(ISERROR(VLOOKUP(B12,'Callsign Database'!A:F,4,0))," ",VLOOKUP(B12,'Callsign Database'!A:F,4,0)) | Q12: =IF(ISERROR(VLOOKUP(A12,'Registration Database'!A:O,15,0))," ",VLOOKUP(A12,'Registration Database'!A:O,15,0)) | R12: =IF(ISERROR(VLOOKUP(A12,'Registration Database'!A:F,6,0))," ",VLOOKUP(A12,'Registration Database'!A:F,6,0)) | S12: =IF(ISERROR(VLOOKUP(B12,'Callsign Database'!A:F,3,0)),"",VLOOKUP(B12,'Callsign Database'!A:F,3,0)) | T12: =IF(D12="loc",2)+IF(OR(D12="DEP",D12="ARR"),"1")+IF(D12="ovr","0") -> 0 | U12: =L12*2 -> 0
B13: =IF(ISERROR(VLOOKUP(A13,'Registration Database'!A:N,13,0)),"",VLOOKUP(A13,'Registration Database'!A:N,13,0)) | C13: =IF(ISERROR(VLOOKUP(A13,'Registration Database'!A:E,3,0))," ",VLOOKUP(A13,'Registration Database'!A:E,3,0)) | D13: =IF(ISNUMBER(SEARCH("UAM", B13)), "LOC", "") | E13: =IF(OR(D13="LOC", D13="OVR"), "V", "") | F13: =IF(OR(D13="DEP",D13="LOC"),"EGOW","") | H13: =IF(OR(D13="ARR",D13="LOC"),"EGOW","") | J13: =IF(ISERROR(VLOOKUP(C13,'WTC Database'!C:G,4,0))," ",VLOOKUP(C13,'WTC Database'!C:G,4,0)) | K13: =IF(ISERROR(VLOOKUP(C13,'WTC Database'!C:G,5,0))," ",VLOOKUP(C13,'WTC Database'!C:G,5,0)) | N13: =IF(D13="OVR",1,0) -> 0 | O13: =IF(ISERROR(VLOOKUP(B13,'Callsign Database'!A:F,4,0))," ",VLOOKUP(B13,'Callsign Database'!A:F,4,0)) | Q13: =IF(ISERROR(VLOOKUP(A13,'Registration Database'!A:O,15,0))," ",VLOOKUP(A13,'Registration Database'!A:O,15,0)) | R13: =IF(ISERROR(VLOOKUP(A13,'Registration Database'!A:F,6,0))," ",VLOOKUP(A13,'Registration Database'!A:F,6,0)) | S13: =IF(ISERROR(VLOOKUP(B13,'Callsign Database'!A:F,3,0)),"",VLOOKUP(B13,'Callsign Database'!A:F,3,0)) | T13: =IF(D13="loc",2)+IF(OR(D13="DEP",D13="ARR"),"1")+IF(D13="ovr","0") -> 0 | U13: =L13*2 -> 0
... B100: =IF(ISERROR(VLOOKUP(A100,'Registration Database'!A:N,13,0)),"",VLOOKUP(A100,'Registration Database'!A:N,13,0)) | C100: =IF(ISERROR(VLOOKUP(A100,'Registration Database'!A:E,3,0))," ",VLOOKUP(A100,'Registration Database'!A:E,3,0)) | D100: =IF(ISNUMBER(SEARCH("UAM", B100)), "LOC", "") | E100: =IF(OR(D100="LOC", D100="OVR"), "V", "") | F100: =IF(OR(D100="DEP",D100="LOC"),"EGOW","") | H100: =IF(OR(D100="ARR",D100="LOC"),"EGOW","") | J100: =IF(ISERROR(VLOOKUP(C100,'WTC Database'!C:G,4,0))," ",VLOOKUP(C100,'WTC Database'!C:G,4,0)) | K100: =IF(ISERROR(VLOOKUP(C100,'WTC Database'!C:G,5,0))," ",VLOOKUP(C100,'WTC Database'!C:G,5,0)) | N100: =IF(D100="OVR",1,0) -> 0 | O100: =IF(ISERROR(VLOOKUP(B100,'Callsign Database'!A:F,4,0))," ",VLOOKUP(B100,'Callsign Database'!A:F,4,0)) | Q100: =IF(ISERROR(VLOOKUP(A100,'Registration Database'!A:O,15,0))," ",VLOOKUP(A100,'Registration Database'!A:O,15,0)) | R100: =IF(ISERROR(VLOOKUP(A100,'Registration Database'!A:F,6,0))," ",VLOOKUP(A100,'Registration Database'!A:F,6,0)) | S100: =IF(ISERROR(VLOOKUP(B100,'Callsign Database'!A:F,3,0)),"",VLOOKUP(B100,'Callsign Database'!A:F,3,0)) | T100: =IF(D100="loc",2)+IF(OR(D100="DEP",D100="ARR"),"1")+IF(D100="ovr","0") -> 0 | U100: =L100*2 -> 0

Sheet 2ND
A1: REGISTRATION | B1: CALLSIGN | C1: ACFT TYPE | D1: FLIGHT TYPE | E1: FLIGHT RULES | F1: DEP POINT | G1: DEP TIME | H1: ARR POINT | I1: ARR TIME | J1: WTC D | K1: WTC A | L1: T&G | M1: O/S | N1: FIS | O1: CAPTAIN | P1: POB | Q1: REMARKS | R1: EGOW Code | S1: Unit Code | T1: Movement Number | U1: T&G Dupliction
B2: =IF(ISERROR(VLOOKUP(A2,'Registration Database'!A:N,13,0)),"",VLOOKUP(A2,'Registration Database'!A:N,13,0)) | C2: =IF(ISERROR(VLOOKUP(A2,'Registration Database'!A:E,3,0))," ",VLOOKUP(A2,'Registration Database'!A:E,3,0)) | D2: =IF(ISNUMBER(SEARCH("UAM", B2)), "LOC", "") | E2: =IF(OR(D2="LOC", D2="OVR"), "V", "") | F2: =IF(OR(D2="DEP",D2="LOC"),"EGOW","") | H2: =IF(OR(D2="ARR",D2="LOC"),"EGOW","") | J2: =IF(ISERROR(VLOOKUP(C2,'WTC Database'!C:G,4,0))," ",VLOOKUP(C2,'WTC Database'!C:G,4,0)) | K2: =IF(ISERROR(VLOOKUP(C2,'WTC Database'!C:G,5,0))," ",VLOOKUP(C2,'WTC Database'!C:G,5,0)) | N2: =IF(D2="OVR",1,0) -> 0 | O2: =IF(ISERROR(VLOOKUP(B2,'Callsign Database'!A:F,4,0))," ",VLOOKUP(B2,'Callsign Database'!A:F,4,0)) | Q2: =IF(ISERROR(VLOOKUP(A2,'Registration Database'!A:O,15,0))," ",VLOOKUP(A2,'Registration Database'!A:O,15,0)) | R2: =IF(ISERROR(VLOOKUP(A2,'Registration Database'!A:F,6,0))," ",VLOOKUP(A2,'Registration Database'!A:F,6,0)) | S2: =IF(ISERROR(VLOOKUP(B2,'Callsign Database'!A:F,3,0)),"",VLOOKUP(B2,'Callsign Database'!A:F,3,0)) | T2: =IF(D2="loc",2)+IF(OR(D2="DEP",D2="ARR"),"1")+IF(D2="ovr","0") -> 0 | U2: =L2*2 -> 0
B3: =IF(ISERROR(VLOOKUP(A3,'Registration Database'!A:N,13,0)),"",VLOOKUP(A3,'Registration Database'!A:N,13,0)) | C3: =IF(ISERROR(VLOOKUP(A3,'Registration Database'!A:E,3,0))," ",VLOOKUP(A3,'Registration Database'!A:E,3,0)) | D3: =IF(ISNUMBER(SEARCH("UAM", B3)), "LOC", "") | E3: =IF(OR(D3="LOC", D3="OVR"), "V", "") | F3: =IF(OR(D3="DEP",D3="LOC"),"EGOW","") | H3: =IF(OR(D3="ARR",D3="LOC"),"EGOW","") | J3: =IF(ISERROR(VLOOKUP(C3,'WTC Database'!C:G,4,0))," ",VLOOKUP(C3,'WTC Database'!C:G,4,0)) | K3: =IF(ISERROR(VLOOKUP(C3,'WTC Database'!C:G,5,0))," ",VLOOKUP(C3,'WTC Database'!C:G,5,0)) | N3: =IF(D3="OVR",1,0) -> 0 | O3: =IF(ISERROR(VLOOKUP(B3,'Callsign Database'!A:F,4,0))," ",VLOOKUP(B3,'Callsign Database'!A:F,4,0)) | Q3: =IF(ISERROR(VLOOKUP(A3,'Registration Database'!A:O,15,0))," ",VLOOKUP(A3,'Registration Database'!A:O,15,0)) | R3: =IF(ISERROR(VLOOKUP(A3,'Registration Database'!A:F,6,0))," ",VLOOKUP(A3,'Registration Database'!A:F,6,0)) | S3: =IF(ISERROR(VLOOKUP(B3,'Callsign Database'!A:F,3,0)),"",VLOOKUP(B3,'Callsign Database'!A:F,3,0)) | T3: =IF(D3="loc",2)+IF(OR(D3="DEP",D3="ARR"),"1")+IF(D3="ovr","0") -> 0 | U3: =L3*2 -> 0
B4: =IF(ISERROR(VLOOKUP(A4,'Registration Database'!A:N,13,0)),"",VLOOKUP(A4,'Registration Database'!A:N,13,0)) | C4: =IF(ISERROR(VLOOKUP(A4,'Registration Database'!A:E,3,0))," ",VLOOKUP(A4,'Registration Database'!A:E,3,0)) | D4: =IF(ISNUMBER(SEARCH("UAM", B4)), "LOC", "") | E4: =IF(OR(D4="LOC", D4="OVR"), "V", "") | F4: =IF(OR(D4="DEP",D4="LOC"),"EGOW","") | H4: =IF(OR(D4="ARR",D4="LOC"),"EGOW","") | J4: =IF(ISERROR(VLOOKUP(C4,'WTC Database'!C:G,4,0))," ",VLOOKUP(C4,'WTC Database'!C:G,4,0)) | K4: =IF(ISERROR(VLOOKUP(C4,'WTC Database'!C:G,5,0))," ",VLOOKUP(C4,'WTC Database'!C:G,5,0)) | N4: =IF(D4="OVR",1,0) -> 0 | O4: =IF(ISERROR(VLOOKUP(B4,'Callsign Database'!A:F,4,0))," ",VLOOKUP(B4,'Callsign Database'!A:F,4,0)) | Q4: =IF(ISERROR(VLOOKUP(A4,'Registration Database'!A:O,15,0))," ",VLOOKUP(A4,'Registration Database'!A:O,15,0)) | R4: =IF(ISERROR(VLOOKUP(A4,'Registration Database'!A:F,6,0))," ",VLOOKUP(A4,'Registration Database'!A:F,6,0)) | S4: =IF(ISERROR(VLOOKUP(B4,'Callsign Database'!A:F,3,0)),"",VLOOKUP(B4,'Callsign Database'!A:F,3,0)) | T4: =IF(D4="loc",2)+IF(OR(D4="DEP",D4="ARR"),"1")+IF(D4="ovr","0") -> 0 | U4: =L4*2 -> 0
B5: =IF(ISERROR(VLOOKUP(A5,'Registration Database'!A:N,13,0)),"",VLOOKUP(A5,'Registration Database'!A:N,13,0)) | C5: =IF(ISERROR(VLOOKUP(A5,'Registration Database'!A:E,3,0))," ",VLOOKUP(A5,'Registration Database'!A:E,3,0)) | D5: =IF(ISNUMBER(SEARCH("UAM", B5)), "LOC", "") | E5: =IF(OR(D5="LOC", D5="OVR"), "V", "") | F5: =IF(OR(D5="DEP",D5="LOC"),"EGOW","") | H5: =IF(OR(D5="ARR",D5="LOC"),"EGOW","") | J5: =IF(ISERROR(VLOOKUP(C5,'WTC Database'!C:G,4,0))," ",VLOOKUP(C5,'WTC Database'!C:G,4,0)) | K5: =IF(ISERROR(VLOOKUP(C5,'WTC Database'!C:G,5,0))," ",VLOOKUP(C5,'WTC Database'!C:G,5,0)) | N5: =IF(D5="OVR",1,0) -> 0 | O5: =IF(ISERROR(VLOOKUP(B5,'Callsign Database'!A:F,4,0))," ",VLOOKUP(B5,'Callsign Database'!A:F,4,0)) | Q5: =IF(ISERROR(VLOOKUP(A5,'Registration Database'!A:O,15,0))," ",VLOOKUP(A5,'Registration Database'!A:O,15,0)) | R5: =IF(ISERROR(VLOOKUP(A5,'Registration Database'!A:F,6,0))," ",VLOOKUP(A5,'Registration Database'!A:F,6,0)) | S5: =IF(ISERROR(VLOOKUP(B5,'Callsign Database'!A:F,3,0)),"",VLOOKUP(B5,'Callsign Database'!A:F,3,0)) | T5: =IF(D5="loc",2)+IF(OR(D5="DEP",D5="ARR"),"1")+IF(D5="ovr","0") -> 0 | U5: =L5*2 -> 0
B6: =IF(ISERROR(VLOOKUP(A6,'Registration Database'!A:N,13,0)),"",VLOOKUP(A6,'Registration Database'!A:N,13,0)) | C6: =IF(ISERROR(VLOOKUP(A6,'Registration Database'!A:E,3,0))," ",VLOOKUP(A6,'Registration Database'!A:E,3,0)) | D6: =IF(ISNUMBER(SEARCH("UAM", B6)), "LOC", "") | E6: =IF(OR(D6="LOC", D6="OVR"), "V", "") | F6: =IF(OR(D6="DEP",D6="LOC"),"EGOW","") | H6: =IF(OR(D6="ARR",D6="LOC"),"EGOW","") | J6: =IF(ISERROR(VLOOKUP(C6,'WTC Database'!C:G,4,0))," ",VLOOKUP(C6,'WTC Database'!C:G,4,0)) | K6: =IF(ISERROR(VLOOKUP(C6,'WTC Database'!C:G,5,0))," ",VLOOKUP(C6,'WTC Database'!C:G,5,0)) | N6: =IF(D6="OVR",1,0) -> 0 | O6: =IF(ISERROR(VLOOKUP(B6,'Callsign Database'!A:F,4,0))," ",VLOOKUP(B6,'Callsign Database'!A:F,4,0)) | Q6: =IF(ISERROR(VLOOKUP(A6,'Registration Database'!A:O,15,0))," ",VLOOKUP(A6,'Registration Database'!A:O,15,0)) | R6: =IF(ISERROR(VLOOKUP(A6,'Registration Database'!A:F,6,0))," ",VLOOKUP(A6,'Registration Database'!A:F,6,0)) | S6: =IF(ISERROR(VLOOKUP(B6,'Callsign Database'!A:F,3,0)),"",VLOOKUP(B6,'Callsign Database'!A:F,3,0)) | T6: =IF(D6="loc",2)+IF(OR(D6="DEP",D6="ARR"),"1")+IF(D6="ovr","0") -> 0 | U6: =L6*2 -> 0
B7: =IF(ISERROR(VLOOKUP(A7,'Registration Database'!A:N,13,0)),"",VLOOKUP(A7,'Registration Database'!A:N,13,0)) | C7: =IF(ISERROR(VLOOKUP(A7,'Registration Database'!A:E,3,0))," ",VLOOKUP(A7,'Registration Database'!A:E,3,0)) | D7: =IF(ISNUMBER(SEARCH("UAM", B7)), "LOC", "") | E7: =IF(OR(D7="LOC", D7="OVR"), "V", "") | F7: =IF(OR(D7="DEP",D7="LOC"),"EGOW","") | H7: =IF(OR(D7="ARR",D7="LOC"),"EGOW","") | J7: =IF(ISERROR(VLOOKUP(C7,'WTC Database'!C:G,4,0))," ",VLOOKUP(C7,'WTC Database'!C:G,4,0)) | K7: =IF(ISERROR(VLOOKUP(C7,'WTC Database'!C:G,5,0))," ",VLOOKUP(C7,'WTC Database'!C:G,5,0)) | N7: =IF(D7="OVR",1,0) -> 0 | O7: =IF(ISERROR(VLOOKUP(B7,'Callsign Database'!A:F,4,0))," ",VLOOKUP(B7,'Callsign Database'!A:F,4,0)) | Q7: =IF(ISERROR(VLOOKUP(A7,'Registration Database'!A:O,15,0))," ",VLOOKUP(A7,'Registration Database'!A:O,15,0)) | R7: =IF(ISERROR(VLOOKUP(A7,'Registration Database'!A:F,6,0))," ",VLOOKUP(A7,'Registration Database'!A:F,6,0)) | S7: =IF(ISERROR(VLOOKUP(B7,'Callsign Database'!A:F,3,0)),"",VLOOKUP(B7,'Callsign Database'!A:F,3,0)) | T7: =IF(D7="loc",2)+IF(OR(D7="DEP",D7="ARR"),"1")+IF(D7="ovr","0") -> 0 | U7: =L7*2 -> 0
B8: =IF(ISERROR(VLOOKUP(A8,'Registration Database'!A:N,13,0)),"",VLOOKUP(A8,'Registration Database'!A:N,13,0)) | C8: =IF(ISERROR(VLOOKUP(A8,'Registration Database'!A:E,3,0))," ",VLOOKUP(A8,'Registration Database'!A:E,3,0)) | D8: =IF(ISNUMBER(SEARCH("UAM", B8)), "LOC", "") | E8: =IF(OR(D8="LOC", D8="OVR"), "V", "") | F8: =IF(OR(D8="DEP",D8="LOC"),"EGOW","") | H8: =IF(OR(D8="ARR",D8="LOC"),"EGOW","") | J8: =IF(ISERROR(VLOOKUP(C8,'WTC Database'!C:G,4,0))," ",VLOOKUP(C8,'WTC Database'!C:G,4,0)) | K8: =IF(ISERROR(VLOOKUP(C8,'WTC Database'!C:G,5,0))," ",VLOOKUP(C8,'WTC Database'!C:G,5,0)) | N8: =IF(D8="OVR",1,0) -> 0 | O8: =IF(ISERROR(VLOOKUP(B8,'Callsign Database'!A:F,4,0))," ",VLOOKUP(B8,'Callsign Database'!A:F,4,0)) | Q8: =IF(ISERROR(VLOOKUP(A8,'Registration Database'!A:O,15,0))," ",VLOOKUP(A8,'Registration Database'!A:O,15,0)) | R8: =IF(ISERROR(VLOOKUP(A8,'Registration Database'!A:F,6,0))," ",VLOOKUP(A8,'Registration Database'!A:F,6,0)) | S8: =IF(ISERROR(VLOOKUP(B8,'Callsign Database'!A:F,3,0)),"",VLOOKUP(B8,'Callsign Database'!A:F,3,0)) | T8: =IF(D8="loc",2)+IF(OR(D8="DEP",D8="ARR"),"1")+IF(D8="ovr","0") -> 0 | U8: =L8*2 -> 0
B9: =IF(ISERROR(VLOOKUP(A9,'Registration Database'!A:N,13,0)),"",VLOOKUP(A9,'Registration Database'!A:N,13,0)) | C9: =IF(ISERROR(VLOOKUP(A9,'Registration Database'!A:E,3,0))," ",VLOOKUP(A9,'Registration Database'!A:E,3,0)) | D9: =IF(ISNUMBER(SEARCH("UAM", B9)), "LOC", "") | E9: =IF(OR(D9="LOC", D9="OVR"), "V", "") | F9: =IF(OR(D9="DEP",D9="LOC"),"EGOW","") | H9: =IF(OR(D9="ARR",D9="LOC"),"EGOW","") | J9: =IF(ISERROR(VLOOKUP(C9,'WTC Database'!C:G,4,0))," ",VLOOKUP(C9,'WTC Database'!C:G,4,0)) | K9: =IF(ISERROR(VLOOKUP(C9,'WTC Database'!C:G,5,0))," ",VLOOKUP(C9,'WTC Database'!C:G,5,0)) | N9: =IF(D9="OVR",1,0) -> 0 | O9: =IF(ISERROR(VLOOKUP(B9,'Callsign Database'!A:F,4,0))," ",VLOOKUP(B9,'Callsign Database'!A:F,4,0)) | Q9: =IF(ISERROR(VLOOKUP(A9,'Registration Database'!A:O,15,0))," ",VLOOKUP(A9,'Registration Database'!A:O,15,0)) | R9: =IF(ISERROR(VLOOKUP(A9,'Registration Database'!A:F,6,0))," ",VLOOKUP(A9,'Registration Database'!A:F,6,0)) | S9: =IF(ISERROR(VLOOKUP(B9,'Callsign Database'!A:F,3,0)),"",VLOOKUP(B9,'Callsign Database'!A:F,3,0)) | T9: =IF(D9="loc",2)+IF(OR(D9="DEP",D9="ARR"),"1")+IF(D9="ovr","0") -> 0 | U9: =L9*2 -> 0
B10: =IF(ISERROR(VLOOKUP(A10,'Registration Database'!A:N,13,0)),"",VLOOKUP(A10,'Registration Database'!A:N,13,0)) | C10: =IF(ISERROR(VLOOKUP(A10,'Registration Database'!A:E,3,0))," ",VLOOKUP(A10,'Registration Database'!A:E,3,0)) | D10: =IF(ISNUMBER(SEARCH("UAM", B10)), "LOC", "") | E10: =IF(OR(D10="LOC", D10="OVR"), "V", "") | F10: =IF(OR(D10="DEP",D10="LOC"),"EGOW","") | H10: =IF(OR(D10="ARR",D10="LOC"),"EGOW","") | J10: =IF(ISERROR(VLOOKUP(C10,'WTC Database'!C:G,4,0))," ",VLOOKUP(C10,'WTC Database'!C:G,4,0)) | K10: =IF(ISERROR(VLOOKUP(C10,'WTC Database'!C:G,5,0))," ",VLOOKUP(C10,'WTC Database'!C:G,5,0)) | N10: =IF(D10="OVR",1,0) -> 0 | O10: =IF(ISERROR(VLOOKUP(B10,'Callsign Database'!A:F,4,0))," ",VLOOKUP(B10,'Callsign Database'!A:F,4,0)) | Q10: =IF(ISERROR(VLOOKUP(A10,'Registration Database'!A:O,15,0))," ",VLOOKUP(A10,'Registration Database'!A:O,15,0)) | R10: =IF(ISERROR(VLOOKUP(A10,'Registration Database'!A:F,6,0))," ",VLOOKUP(A10,'Registration Database'!A:F,6,0)) | S10: =IF(ISERROR(VLOOKUP(B10,'Callsign Database'!A:F,3,0)),"",VLOOKUP(B10,'Callsign Database'!A:F,3,0)) | T10: =IF(D10="loc",2)+IF(OR(D10="DEP",D10="ARR"),"1")+IF(D10="ovr","0") -> 0 | U10: =L10*2 -> 0
B11: =IF(ISERROR(VLOOKUP(A11,'Registration Database'!A:N,13,0)),"",VLOOKUP(A11,'Registration Database'!A:N,13,0)) | C11: =IF(ISERROR(VLOOKUP(A11,'Registration Database'!A:E,3,0))," ",VLOOKUP(A11,'Registration Database'!A:E,3,0)) | D11: =IF(ISNUMBER(SEARCH("UAM", B11)), "LOC", "") | E11: =IF(OR(D11="LOC", D11="OVR"), "V", "") | F11: =IF(OR(D11="DEP",D11="LOC"),"EGOW","") | H11: =IF(OR(D11="ARR",D11="LOC"),"EGOW","") | J11: =IF(ISERROR(VLOOKUP(C11,'WTC Database'!C:G,4,0))," ",VLOOKUP(C11,'WTC Database'!C:G,4,0)) | K11: =IF(ISERROR(VLOOKUP(C11,'WTC Database'!C:G,5,0))," ",VLOOKUP(C11,'WTC Database'!C:G,5,0)) | N11: =IF(D11="OVR",1,0) -> 0 | O11: =IF(ISERROR(VLOOKUP(B11,'Callsign Database'!A:F,4,0))," ",VLOOKUP(B11,'Callsign Database'!A:F,4,0)) | Q11: =IF(ISERROR(VLOOKUP(A11,'Registration Database'!A:O,15,0))," ",VLOOKUP(A11,'Registration Database'!A:O,15,0)) | R11: =IF(ISERROR(VLOOKUP(A11,'Registration Database'!A:F,6,0))," ",VLOOKUP(A11,'Registration Database'!A:F,6,0)) | S11: =IF(ISERROR(VLOOKUP(B11,'Callsign Database'!A:F,3,0)),"",VLOOKUP(B11,'Callsign Database'!A:F,3,0)) | T11: =IF(D11="loc",2)+IF(OR(D11="DEP",D11="ARR"),"1")+IF(D11="ovr","0") -> 0 | U11: =L11*2 -> 0
B12: =IF(ISERROR(VLOOKUP(A12,'Registration Database'!A:N,13,0)),"",VLOOKUP(A12,'Registration Database'!A:N,13,0)) | C12: =IF(ISERROR(VLOOKUP(A12,'Registration Database'!A:E,3,0))," ",VLOOKUP(A12,'Registration Database'!A:E,3,0)) | D12: =IF(ISNUMBER(SEARCH("UAM", B12)), "LOC", "") | E12: =IF(OR(D12="LOC", D12="OVR"), "V", "") | F12: =IF(OR(D12="DEP",D12="LOC"),"EGOW","") | H12: =IF(OR(D12="ARR",D12="LOC"),"EGOW","") | J12: =IF(ISERROR(VLOOKUP(C12,'WTC Database'!C:G,4,0))," ",VLOOKUP(C12,'WTC Database'!C:G,4,0)) | K12: =IF(ISERROR(VLOOKUP(C12,'WTC Database'!C:G,5,0))," ",VLOOKUP(C12,'WTC Database'!C:G,5,0)) | N12: =IF(D12="OVR",1,0) -> 0 | O12: =IF(ISERROR(VLOOKUP(B12,'Callsign Database'!A:F,4,0))," ",VLOOKUP(B12,'Callsign Database'!A:F,4,0)) | Q12: =IF(ISERROR(VLOOKUP(A12,'Registration Database'!A:O,15,0))," ",VLOOKUP(A12,'Registration Database'!A:O,15,0)) | R12: =IF(ISERROR(VLOOKUP(A12,'Registration Database'!A:F,6,0))," ",VLOOKUP(A12,'Registration Database'!A:F,6,0)) | S12: =IF(ISERROR(VLOOKUP(B12,'Callsign Database'!A:F,3,0)),"",VLOOKUP(B12,'Callsign Database'!A:F,3,0)) | T12: =IF(D12="loc",2)+IF(OR(D12="DEP",D12="ARR"),"1")+IF(D12="ovr","0") -> 0 | U12: =L12*2 -> 0
B13: =IF(ISERROR(VLOOKUP(A13,'Registration Database'!A:N,13,0)),"",VLOOKUP(A13,'Registration Database'!A:N,13,0)) | C13: =IF(ISERROR(VLOOKUP(A13,'Registration Database'!A:E,3,0))," ",VLOOKUP(A13,'Registration Database'!A:E,3,0)) | D13: =IF(ISNUMBER(SEARCH("UAM", B13)), "LOC", "") | E13: =IF(OR(D13="LOC", D13="OVR"), "V", "") | F13: =IF(OR(D13="DEP",D13="LOC"),"EGOW","") | H13: =IF(OR(D13="ARR",D13="LOC"),"EGOW","") | J13: =IF(ISERROR(VLOOKUP(C13,'WTC Database'!C:G,4,0))," ",VLOOKUP(C13,'WTC Database'!C:G,4,0)) | K13: =IF(ISERROR(VLOOKUP(C13,'WTC Database'!C:G,5,0))," ",VLOOKUP(C13,'WTC Database'!C:G,5,0)) | N13: =IF(D13="OVR",1,0) -> 0 | O13: =IF(ISERROR(VLOOKUP(B13,'Callsign Database'!A:F,4,0))," ",VLOOKUP(B13,'Callsign Database'!A:F,4,0)) | Q13: =IF(ISERROR(VLOOKUP(A13,'Registration Database'!A:O,15,0))," ",VLOOKUP(A13,'Registration Database'!A:O,15,0)) | R13: =IF(ISERROR(VLOOKUP(A13,'Registration Database'!A:F,6,0))," ",VLOOKUP(A13,'Registration Database'!A:F,6,0)) | S13: =IF(ISERROR(VLOOKUP(B13,'Callsign Database'!A:F,3,0)),"",VLOOKUP(B13,'Callsign Database'!A:F,3,0)) | T13: =IF(D13="loc",2)+IF(OR(D13="DEP",D13="ARR"),"1")+IF(D13="ovr","0") -> 0 | U13: =L13*2 -> 0
... B100: =IF(ISERROR(VLOOKUP(A100,'Registration Database'!A:N,13,0)),"",VLOOKUP(A100,'Registration Database'!A:N,13,0)) | C100: =IF(ISERROR(VLOOKUP(A100,'Registration Database'!A:E,3,0))," ",VLOOKUP(A100,'Registration Database'!A:E,3,0)) | D100: =IF(ISNUMBER(SEARCH("UAM", B100)), "LOC", "") | E100: =IF(OR(D100="LOC", D100="OVR"), "V", "") | F100: =IF(OR(D100="DEP",D100="LOC"),"EGOW","") | H100: =IF(OR(D100="ARR",D100="LOC"),"EGOW","") | J100: =IF(ISERROR(VLOOKUP(C100,'WTC Database'!C:G,4,0))," ",VLOOKUP(C100,'WTC Database'!C:G,4,0)) | K100: =IF(ISERROR(VLOOKUP(C100,'WTC Database'!C:G,5,0))," ",VLOOKUP(C100,'WTC Database'!C:G,5,0)) | N100: =IF(D100="OVR",1,0) -> 0 | O100: =IF(ISERROR(VLOOKUP(B100,'Callsign Database'!A:F,4,0))," ",VLOOKUP(B100,'Callsign Database'!A:F,4,0)) | Q100: =IF(ISERROR(VLOOKUP(A100,'Registration Database'!A:O,15,0))," ",VLOOKUP(A100,'Registration Database'!A:O,15,0)) | R100: =IF(ISERROR(VLOOKUP(A100,'Registration Database'!A:F,6,0))," ",VLOOKUP(A100,'Registration Database'!A:F,6,0)) | S100: =IF(ISERROR(VLOOKUP(B100,'Callsign Database'!A:F,3,0)),"",VLOOKUP(B100,'Callsign Database'!A:F,3,0)) | T100: =IF(D100="loc",2)+IF(OR(D100="DEP",D100="ARR"),"1")+IF(D100="ovr","0") -> 0 | U100: =L100*2 -> 0

Sheet 3RD
A1: REGISTRATION | B1: CALLSIGN | C1: ACFT TYPE | D1: FLIGHT TYPE | E1: FLIGHT RULES | F1: DEP POINT | G1: DEP TIME | H1: ARR POINT | I1: ARR TIME | J1: WTC D | K1: WTC A | L1: T&G | M1: O/S | N1: FIS | O1: CAPTAIN | P1: POB | Q1: REMARKS | R1: EGOW Code | S1: Unit Code | T1: Movement Number | U1: T&G Dupliction
B2: =IF(ISERROR(VLOOKUP(A2,'Registration Database'!A:N,13,0)),"",VLOOKUP(A2,'Registration Database'!A:N,13,0)) | C2: =IF(ISERROR(VLOOKUP(A2,'Registration Database'!A:E,3,0))," ",VLOOKUP(A2,'Registration Database'!A:E,3,0)) | D2: =IF(ISNUMBER(SEARCH("UAM", B2)), "LOC", "") | E2: =IF(OR(D2="LOC", D2="OVR"), "V", "") | F2: =IF(OR(D2="DEP",D2="LOC"),"EGOW","") | H2: =IF(OR(D2="ARR",D2="LOC"),"EGOW","") | J2: =IF(ISERROR(VLOOKUP(C2,'WTC Database'!C:G,4,0))," ",VLOOKUP(C2,'WTC Database'!C:G,4,0)) | K2: =IF(ISERROR(VLOOKUP(C2,'WTC Database'!C:G,5,0))," ",VLOOKUP(C2,'WTC Database'!C:G,5,0)) | N2: =IF(D2="OVR",1,0) -> 0 | O2: =IF(ISERROR(VLOOKUP(B2,'Callsign Database'!A:F,4,0))," ",VLOOKUP(B2,'Callsign Database'!A:F,4,0)) | Q2: =IF(ISERROR(VLOOKUP(A2,'Registration Database'!A:O,15,0))," ",VLOOKUP(A2,'Registration Database'!A:O,15,0)) | R2: =IF(ISERROR(VLOOKUP(A2,'Registration Database'!A:F,6,0))," ",VLOOKUP(A2,'Registration Database'!A:F,6,0)) | S2: =IF(ISERROR(VLOOKUP(B2,'Callsign Database'!A:F,3,0)),"",VLOOKUP(B2,'Callsign Database'!A:F,3,0)) | T2: =IF(D2="loc",2)+IF(OR(D2="DEP",D2="ARR"),"1")+IF(D2="ovr","0") -> 0 | U2: =L2*2 -> 0
B3: =IF(ISERROR(VLOOKUP(A3,'Registration Database'!A:N,13,0)),"",VLOOKUP(A3,'Registration Database'!A:N,13,0)) | C3: =IF(ISERROR(VLOOKUP(A3,'Registration Database'!A:E,3,0))," ",VLOOKUP(A3,'Registration Database'!A:E,3,0)) | D3: =IF(ISNUMBER(SEARCH("UAM", B3)), "LOC", "") | E3: =IF(OR(D3="LOC", D3="OVR"), "V", "") | F3: =IF(OR(D3="DEP",D3="LOC"),"EGOW","") | H3: =IF(OR(D3="ARR",D3="LOC"),"EGOW","") | J3: =IF(ISERROR(VLOOKUP(C3,'WTC Database'!C:G,4,0))," ",VLOOKUP(C3,'WTC Database'!C:G,4,0)) | K3: =IF(ISERROR(VLOOKUP(C3,'WTC Database'!C:G,5,0))," ",VLOOKUP(C3,'WTC Database'!C:G,5,0)) | N3: =IF(D3="OVR",1,0) -> 0 | O3: =IF(ISERROR(VLOOKUP(B3,'Callsign Database'!A:F,4,0))," ",VLOOKUP(B3,'Callsign Database'!A:F,4,0)) | Q3: =IF(ISERROR(VLOOKUP(A3,'Registration Database'!A:O,15,0))," ",VLOOKUP(A3,'Registration Database'!A:O,15,0)) | R3: =IF(ISERROR(VLOOKUP(A3,'Registration Database'!A:F,6,0))," ",VLOOKUP(A3,'Registration Database'!A:F,6,0)) | S3: =IF(ISERROR(VLOOKUP(B3,'Callsign Database'!A:F,3,0)),"",VLOOKUP(B3,'Callsign Database'!A:F,3,0)) | T3: =IF(D3="loc",2)+IF(OR(D3="DEP",D3="ARR"),"1")+IF(D3="ovr","0") -> 0 | U3: =L3*2 -> 0
B4: =IF(ISERROR(VLOOKUP(A4,'Registration Database'!A:N,13,0)),"",VLOOKUP(A4,'Registration Database'!A:N,13,0)) | C4: =IF(ISERROR(VLOOKUP(A4,'Registration Database'!A:E,3,0))," ",VLOOKUP(A4,'Registration Database'!A:E,3,0)) | D4: =IF(ISNUMBER(SEARCH("UAM", B4)), "LOC", "") | E4: =IF(OR(D4="LOC", D4="OVR"), "V", "") | F4: =IF(OR(D4="DEP",D4="LOC"),"EGOW","") | H4: =IF(OR(D4="ARR",D4="LOC"),"EGOW","") | J4: =IF(ISERROR(VLOOKUP(C4,'WTC Database'!C:G,4,0))," ",VLOOKUP(C4,'WTC Database'!C:G,4,0)) | K4: =IF(ISERROR(VLOOKUP(C4,'WTC Database'!C:G,5,0))," ",VLOOKUP(C4,'WTC Database'!C:G,5,0)) | N4: =IF(D4="OVR",1,0) -> 0 | O4: =IF(ISERROR(VLOOKUP(B4,'Callsign Database'!A:F,4,0))," ",VLOOKUP(B4,'Callsign Database'!A:F,4,0)) | Q4: =IF(ISERROR(VLOOKUP(A4,'Registration Database'!A:O,15,0))," ",VLOOKUP(A4,'Registration Database'!A:O,15,0)) | R4: =IF(ISERROR(VLOOKUP(A4,'Registration Database'!A:F,6,0))," ",VLOOKUP(A4,'Registration Database'!A:F,6,0)) | S4: =IF(ISERROR(VLOOKUP(B4,'Callsign Database'!A:F,3,0)),"",VLOOKUP(B4,'Callsign Database'!A:F,3,0)) | T4: =IF(D4="loc",2)+IF(OR(D4="DEP",D4="ARR"),"1")+IF(D4="ovr","0") -> 0 | U4: =L4*2 -> 0
B5: =IF(ISERROR(VLOOKUP(A5,'Registration Database'!A:N,13,0)),"",VLOOKUP(A5,'Registration Database'!A:N,13,0)) | C5: =IF(ISERROR(VLOOKUP(A5,'Registration Database'!A:E,3,0))," ",VLOOKUP(A5,'Registration Database'!A:E,3,0)) | D5: =IF(ISNUMBER(SEARCH("UAM", B5)), "LOC", "") | E5: =IF(OR(D5="LOC", D5="OVR"), "V", "") | F5: =IF(OR(D5="DEP",D5="LOC"),"EGOW","") | H5: =IF(OR(D5="ARR",D5="LOC"),"EGOW","") | J5: =IF(ISERROR(VLOOKUP(C5,'WTC Database'!C:G,4,0))," ",VLOOKUP(C5,'WTC Database'!C:G,4,0)) | K5: =IF(ISERROR(VLOOKUP(C5,'WTC Database'!C:G,5,0))," ",VLOOKUP(C5,'WTC Database'!C:G,5,0)) | N5: =IF(D5="OVR",1,0) -> 0 | O5: =IF(ISERROR(VLOOKUP(B5,'Callsign Database'!A:F,4,0))," ",VLOOKUP(B5,'Callsign Database'!A:F,4,0)) | Q5: =IF(ISERROR(VLOOKUP(A5,'Registration Database'!A:O,15,0))," ",VLOOKUP(A5,'Registration Database'!A:O,15,0)) | R5: =IF(ISERROR(VLOOKUP(A5,'Registration Database'!A:F,6,0))," ",VLOOKUP(A5,'Registration Database'!A:F,6,0)) | S5: =IF(ISERROR(VLOOKUP(B5,'Callsign Database'!A:F,3,0)),"",VLOOKUP(B5,'Callsign Database'!A:F,3,0)) | T5: =IF(D5="loc",2)+IF(OR(D5="DEP",D5="ARR"),"1")+IF(D5="ovr","0") -> 0 | U5: =L5*2 -> 0
B6: =IF(ISERROR(VLOOKUP(A6,'Registration Database'!A:N,13,0)),"",VLOOKUP(A6,'Registration Database'!A:N,13,0)) | C6: =IF(ISERROR(VLOOKUP(A6,'Registration Database'!A:E,3,0))," ",VLOOKUP(A6,'Registration Database'!A:E,3,0)) | D6: =IF(ISNUMBER(SEARCH("UAM", B6)), "LOC", "") | E6: =IF(OR(D6="LOC", D6="OVR"), "V", "") | F6: =IF(OR(D6="DEP",D6="LOC"),"EGOW","") | H6: =IF(OR(D6="ARR",D6="LOC"),"EGOW","") | J6: =IF(ISERROR(VLOOKUP(C6,'WTC Database'!C:G,4,0))," ",VLOOKUP(C6,'WTC Database'!C:G,4,0)) | K6: =IF(ISERROR(VLOOKUP(C6,'WTC Database'!C:G,5,0))," ",VLOOKUP(C6,'WTC Database'!C:G,5,0)) | N6: =IF(D6="OVR",1,0) -> 0 | O6: =IF(ISERROR(VLOOKUP(B6,'Callsign Database'!A:F,4,0))," ",VLOOKUP(B6,'Callsign Database'!A:F,4,0)) | Q6: =IF(ISERROR(VLOOKUP(A6,'Registration Database'!A:O,15,0))," ",VLOOKUP(A6,'Registration Database'!A:O,15,0)) | R6: =IF(ISERROR(VLOOKUP(A6,'Registration Database'!A:F,6,0))," ",VLOOKUP(A6,'Registration Database'!A:F,6,0)) | S6: =IF(ISERROR(VLOOKUP(B6,'Callsign Database'!A:F,3,0)),"",VLOOKUP(B6,'Callsign Database'!A:F,3,0)) | T6: =IF(D6="loc",2)+IF(OR(D6="DEP",D6="ARR"),"1")+IF(D6="ovr","0") -> 0 | U6: =L6*2 -> 0
B7: =IF(ISERROR(VLOOKUP(A7,'Registration Database'!A:N,13,0)),"",VLOOKUP(A7,'Registration Database'!A:N,13,0)) | C7: =IF(ISERROR(VLOOKUP(A7,'Registration Database'!A:E,3,0))," ",VLOOKUP(A7,'Registration Database'!A:E,3,0)) | D7: =IF(ISNUMBER(SEARCH("UAM", B7)), "LOC", "") | E7: =IF(OR(D7="LOC", D7="OVR"), "V", "") | F7: =IF(OR(D7="DEP",D7="LOC"),"EGOW","") | H7: =IF(OR(D7="ARR",D7="LOC"),"EGOW","") | J7: =IF(ISERROR(VLOOKUP(C7,'WTC Database'!C:G,4,0))," ",VLOOKUP(C7,'WTC Database'!C:G,4,0)) | K7: =IF(ISERROR(VLOOKUP(C7,'WTC Database'!C:G,5,0))," ",VLOOKUP(C7,'WTC Database'!C:G,5,0)) | N7: =IF(D7="OVR",1,0) -> 0 | O7: =IF(ISERROR(VLOOKUP(B7,'Callsign Database'!A:F,4,0))," ",VLOOKUP(B7,'Callsign Database'!A:F,4,0)) | Q7: =IF(ISERROR(VLOOKUP(A7,'Registration Database'!A:O,15,0))," ",VLOOKUP(A7,'Registration Database'!A:O,15,0)) | R7: =IF(ISERROR(VLOOKUP(A7,'Registration Database'!A:F,6,0))," ",VLOOKUP(A7,'Registration Database'!A:F,6,0)) | S7: =IF(ISERROR(VLOOKUP(B7,'Callsign Database'!A:F,3,0)),"",VLOOKUP(B7,'Callsign Database'!A:F,3,0)) | T7: =IF(D7="loc",2)+IF(OR(D7="DEP",D7="ARR"),"1")+IF(D7="ovr","0") -> 0 | U7: =L7*2 -> 0
B8: =IF(ISERROR(VLOOKUP(A8,'Registration Database'!A:N,13,0)),"",VLOOKUP(A8,'Registration Database'!A:N,13,0)) | C8: =IF(ISERROR(VLOOKUP(A8,'Registration Database'!A:E,3,0))," ",VLOOKUP(A8,'Registration Database'!A:E,3,0)) | D8: =IF(ISNUMBER(SEARCH("UAM", B8)), "LOC", "") | E8: =IF(OR(D8="LOC", D8="OVR"), "V", "") | F8: =IF(OR(D8="DEP",D8="LOC"),"EGOW","") | H8: =IF(OR(D8="ARR",D8="LOC"),"EGOW","") | J8: =IF(ISERROR(VLOOKUP(C8,'WTC Database'!C:G,4,0))," ",VLOOKUP(C8,'WTC Database'!C:G,4,0)) | K8: =IF(ISERROR(VLOOKUP(C8,'WTC Database'!C:G,5,0))," ",VLOOKUP(C8,'WTC Database'!C:G,5,0)) | N8: =IF(D8="OVR",1,0) -> 0 | O8: =IF(ISERROR(VLOOKUP(B8,'Callsign Database'!A:F,4,0))," ",VLOOKUP(B8,'Callsign Database'!A:F,4,0)) | Q8: =IF(ISERROR(VLOOKUP(A8,'Registration Database'!A:O,15,0))," ",VLOOKUP(A8,'Registration Database'!A:O,15,0)) | R8: =IF(ISERROR(VLOOKUP(A8,'Registration Database'!A:F,6,0))," ",VLOOKUP(A8,'Registration Database'!A:F,6,0)) | S8: =IF(ISERROR(VLOOKUP(B8,'Callsign Database'!A:F,3,0)),"",VLOOKUP(B8,'Callsign Database'!A:F,3,0)) | T8: =IF(D8="loc",2)+IF(OR(D8="DEP",D8="ARR"),"1")+IF(D8="ovr","0") -> 0 | U8: =L8*2 -> 0
B9: =IF(ISERROR(VLOOKUP(A9,'Registration Database'!A:N,13,0)),"",VLOOKUP(A9,'Registration Database'!A:N,13,0)) | C9: =IF(ISERROR(VLOOKUP(A9,'Registration Database'!A:E,3,0))," ",VLOOKUP(A9,'Registration Database'!A:E,3,0)) | D9: =IF(ISNUMBER(SEARCH("UAM", B9)), "LOC", "") | E9: =IF(OR(D9="LOC", D9="OVR"), "V", "") | F9: =IF(OR(D9="DEP",D9="LOC"),"EGOW","") | H9: =IF(OR(D9="ARR",D9="LOC"),"EGOW","") | J9: =IF(ISERROR(VLOOKUP(C9,'WTC Database'!C:G,4,0))," ",VLOOKUP(C9,'WTC Database'!C:G,4,0)) | K9: =IF(ISERROR(VLOOKUP(C9,'WTC Database'!C:G,5,0))," ",VLOOKUP(C9,'WTC Database'!C:G,5,0)) | N9: =IF(D9="OVR",1,0) -> 0 | O9: =IF(ISERROR(VLOOKUP(B9,'Callsign Database'!A:F,4,0))," ",VLOOKUP(B9,'Callsign Database'!A:F,4,0)) | Q9: =IF(ISERROR(VLOOKUP(A9,'Registration Database'!A:O,15,0))," ",VLOOKUP(A9,'Registration Database'!A:O,15,0)) | R9: =IF(ISERROR(VLOOKUP(A9,'Registration Database'!A:F,6,0))," ",VLOOKUP(A9,'Registration Database'!A:F,6,0)) | S9: =IF(ISERROR(VLOOKUP(B9,'Callsign Database'!A:F,3,0)),"",VLOOKUP(B9,'Callsign Database'!A:F,3,0)) | T9: =IF(D9="loc",2)+IF(OR(D9="DEP",D9="ARR"),"1")+IF(D9="ovr","0") -> 0 | U9: =L9*2 -> 0
B10: =IF(ISERROR(VLOOKUP(A10,'Registration Database'!A:N,13,0)),"",VLOOKUP(A10,'Registration Database'!A:N,13,0)) | C10: =IF(ISERROR(VLOOKUP(A10,'Registration Database'!A:E,3,0))," ",VLOOKUP(A10,'Registration Database'!A:E,3,0)) | D10: =IF(ISNUMBER(SEARCH("UAM", B10)), "LOC", "") | E10: =IF(OR(D10="LOC", D10="OVR"), "V", "") | F10: =IF(OR(D10="DEP",D10="LOC"),"EGOW","") | H10: =IF(OR(D10="ARR",D10="LOC"),"EGOW","") | J10: =IF(ISERROR(VLOOKUP(C10,'WTC Database'!C:G,4,0))," ",VLOOKUP(C10,'WTC Database'!C:G,4,0)) | K10: =IF(ISERROR(VLOOKUP(C10,'WTC Database'!C:G,5,0))," ",VLOOKUP(C10,'WTC Database'!C:G,5,0)) | N10: =IF(D10="OVR",1,0) -> 0 | O10: =IF(ISERROR(VLOOKUP(B10,'Callsign Database'!A:F,4,0))," ",VLOOKUP(B10,'Callsign Database'!A:F,4,0)) | Q10: =IF(ISERROR(VLOOKUP(A10,'Registration Database'!A:O,15,0))," ",VLOOKUP(A10,'Registration Database'!A:O,15,0)) | R10: =IF(ISERROR(VLOOKUP(A10,'Registration Database'!A:F,6,0))," ",VLOOKUP(A10,'Registration Database'!A:F,6,0)) | S10: =IF(ISERROR(VLOOKUP(B10,'Callsign Database'!A:F,3,0)),"",VLOOKUP(B10,'Callsign Database'!A:F,3,0)) | T10: =IF(D10="loc",2)+IF(OR(D10="DEP",D10="ARR"),"1")+IF(D10="ovr","0") -> 0 | U10: =L10*2 -> 0
B11: =IF(ISERROR(VLOOKUP(A11,'Registration Database'!A:N,13,0)),"",VLOOKUP(A11,'Registration Database'!A:N,13,0)) | C11: =IF(ISERROR(VLOOKUP(A11,'Registration Database'!A:E,3,0))," ",VLOOKUP(A11,'Registration Database'!A:E,3,0)) | D11: =IF(ISNUMBER(SEARCH("UAM", B11)), "LOC", "") | E11: =IF(OR(D11="LOC", D11="OVR"), "V", "") | F11: =IF(OR(D11="DEP",D11="LOC"),"EGOW","") | H11: =IF(OR(D11="ARR",D11="LOC"),"EGOW","") | J11: =IF(ISERROR(VLOOKUP(C11,'WTC Database'!C:G,4,0))," ",VLOOKUP(C11,'WTC Database'!C:G,4,0)) | K11: =IF(ISERROR(VLOOKUP(C11,'WTC Database'!C:G,5,0))," ",VLOOKUP(C11,'WTC Database'!C:G,5,0)) | N11: =IF(D11="OVR",1,0) -> 0 | O11: =IF(ISERROR(VLOOKUP(B11,'Callsign Database'!A:F,4,0))," ",VLOOKUP(B11,'Callsign Database'!A:F,4,0)) | Q11: =IF(ISERROR(VLOOKUP(A11,'Registration Database'!A:O,15,0))," ",VLOOKUP(A11,'Registration Database'!A:O,15,0)) | R11: =IF(ISERROR(VLOOKUP(A11,'Registration Database'!A:F,6,0))," ",VLOOKUP(A11,'Registration Database'!A:F,6,0)) | S11: =IF(ISERROR(VLOOKUP(B11,'Callsign Database'!A:F,3,0)),"",VLOOKUP(B11,'Callsign Database'!A:F,3,0)) | T11: =IF(D11="loc",2)+IF(OR(D11="DEP",D11="ARR"),"1")+IF(D11="ovr","0") -> 0 | U11: =L11*2 -> 0
B12: =IF(ISERROR(VLOOKUP(A12,'Registration Database'!A:N,13,0)),"",VLOOKUP(A12,'Registration Database'!A:N,13,0)) | C12: =IF(ISERROR(VLOOKUP(A12,'Registration Database'!A:E,3,0))," ",VLOOKUP(A12,'Registration Database'!A:E,3,0)) | D12: =IF(ISNUMBER(SEARCH("UAM", B12)), "LOC", "") | E12: =IF(OR(D12="LOC", D12="OVR"), "V", "") | F12: =IF(OR(D12="DEP",D12="LOC"),"EGOW","") | H12: =IF(OR(D12="ARR",D12="LOC"),"EGOW","") | J12: =IF(ISERROR(VLOOKUP(C12,'WTC Database'!C:G,4,0))," ",VLOOKUP(C12,'WTC Database'!C:G,4,0)) | K12: =IF(ISERROR(VLOOKUP(C12,'WTC Database'!C:G,5,0))," ",VLOOKUP(C12,'WTC Database'!C:G,5,0)) | N12: =IF(D12="OVR",1,0) -> 0 | O12: =IF(ISERROR(VLOOKUP(B12,'Callsign Database'!A:F,4,0))," ",VLOOKUP(B12,'Callsign Database'!A:F,4,0)) | Q12: =IF(ISERROR(VLOOKUP(A12,'Registration Database'!A:O,15,0))," ",VLOOKUP(A12,'Registration Database'!A:O,15,0)) | R12: =IF(ISERROR(VLOOKUP(A12,'Registration Database'!A:F,6,0))," ",VLOOKUP(A12,'Registration Database'!A:F,6,0)) | S12: =IF(ISERROR(VLOOKUP(B12,'Callsign Database'!A:F,3,0)),"",VLOOKUP(B12,'Callsign Database'!A:F,3,0)) | T12: =IF(D12="loc",2)+IF(OR(D12="DEP",D12="ARR"),"1")+IF(D12="ovr","0") -> 0 | U12: =L12*2 -> 0
B13: =IF(ISERROR(VLOOKUP(A13,'Registration Database'!A:N,13,0)),"",VLOOKUP(A13,'Registration Database'!A:N,13,0)) | C13: =IF(ISERROR(VLOOKUP(A13,'Registration Database'!A:E,3,0))," ",VLOOKUP(A13,'Registration Database'!A:E,3,0)) | D13: =IF(ISNUMBER(SEARCH("UAM", B13)), "LOC", "") | E13: =IF(OR(D13="LOC", D13="OVR"), "V", "") | F13: =IF(OR(D13="DEP",D13="LOC"),"EGOW","") | H13: =IF(OR(D13="ARR",D13="LOC"),"EGOW","") | J13: =IF(ISERROR(VLOOKUP(C13,'WTC Database'!C:G,4,0))," ",VLOOKUP(C13,'WTC Database'!C:G,4,0)) | K13: =IF(ISERROR(VLOOKUP(C13,'WTC Database'!C:G,5,0))," ",VLOOKUP(C13,'WTC Database'!C:G,5,0)) | N13: =IF(D13="OVR",1,0) -> 0 | O13: =IF(ISERROR(VLOOKUP(B13,'Callsign Database'!A:F,4,0))," ",VLOOKUP(B13,'Callsign Database'!A:F,4,0)) | Q13: =IF(ISERROR(VLOOKUP(A13,'Registration Database'!A:O,15,0))," ",VLOOKUP(A13,'Registration Database'!A:O,15,0)) | R13: =IF(ISERROR(VLOOKUP(A13,'Registration Database'!A:F,6,0))," ",VLOOKUP(A13,'Registration Database'!A:F,6,0)) | S13: =IF(ISERROR(VLOOKUP(B13,'Callsign Database'!A:F,3,0)),"",VLOOKUP(B13,'Callsign Database'!A:F,3,0)) | T13: =IF(D13="loc",2)+IF(OR(D13="DEP",D13="ARR"),"1")+IF(D13="ovr","0") -> 0 | U13: =L13*2 -> 0
... B100: =IF(ISERROR(VLOOKUP(A100,'Registration Database'!A:N,13,0)),"",VLOOKUP(A100,'Registration Database'!A:N,13,0)) | C100: =IF(ISERROR(VLOOKUP(A100,'Registration Database'!A:E,3,0))," ",VLOOKUP(A100,'Registration Database'!A:E,3,0)) | D100: =IF(ISNUMBER(SEARCH("UAM", B100)), "LOC", "") | E100: =IF(OR(D100="LOC", D100="OVR"), "V", "") | F100: =IF(OR(D100="DEP",D100="LOC"),"EGOW","") | H100: =IF(OR(D100="ARR",D100="LOC"),"EGOW","") | J100: =IF(ISERROR(VLOOKUP(C100,'WTC Database'!C:G,4,0))," ",VLOOKUP(C100,'WTC Database'!C:G,4,0)) | K100: =IF(ISERROR(VLOOKUP(C100,'WTC Database'!C:G,5,0))," ",VLOOKUP(C100,'WTC Database'!C:G,5,0)) | N100: =IF(D100="OVR",1,0) -> 0 | O100: =IF(ISERROR(VLOOKUP(B100,'Callsign Database'!A:F,4,0))," ",VLOOKUP(B100,'Callsign Database'!A:F,4,0)) | Q100: =IF(ISERROR(VLOOKUP(A100,'Registration Database'!A:O,15,0))," ",VLOOKUP(A100,'Registration Database'!A:O,15,0)) | R100: =IF(ISERROR(VLOOKUP(A100,'Registration Database'!A:F,6,0))," ",VLOOKUP(A100,'Registration Database'!A:F,6,0)) | S100: =IF(ISERROR(VLOOKUP(B100,'Callsign Database'!A:F,3,0)),"",VLOOKUP(B100,'Callsign Database'!A:F,3,0)) | T100: =IF(D100="loc",2)+IF(OR(D100="DEP",D100="ARR"),"1")+IF(D100="ovr","0") -> 0 | U100: =L100*2 -> 0

Sheet 4TH
A1: REGISTRATION | B1: CALLSIGN | C1: ACFT TYPE | D1: FLIGHT TYPE | E1: FLIGHT RULES | F1: DEP POINT | G1: DEP TIME | H1: ARR POINT | I1: ARR TIME | J1: WTC D | K1: WTC A | L1: T&G | M1: O/S | N1: FIS | O1: CAPTAIN | P1: POB | Q1: REMARKS | R1: EGOW Code | S1: Unit Code | T1: Movement Number | U1: T&G Dupliction
B2: =IF(ISERROR(VLOOKUP(A2,'Registration Database'!A:N,13,0)),"",VLOOKUP(A2,'Registration Database'!A:N,13,0)) | C2: =IF(ISERROR(VLOOKUP(A2,'Registration Database'!A:E,3,0))," ",VLOOKUP(A2,'Registration Database'!A:E,3,0)) | D2: =IF(ISNUMBER(SEARCH("UAM", B2)), "LOC", "") | E2: =IF(OR(D2="LOC", D2="OVR"), "V", "") | F2: =IF(OR(D2="DEP",D2="LOC"),"EGOW","") | H2: =IF(OR(D2="ARR",D2="LOC"),"EGOW","") | J2: =IF(ISERROR(VLOOKUP(C2,'WTC Database'!C:G,4,0))," ",VLOOKUP(C2,'WTC Database'!C:G,4,0)) | K2: =IF(ISERROR(VLOOKUP(C2,'WTC Database'!C:G,5,0))," ",VLOOKUP(C2,'WTC Database'!C:G,5,0)) | N2: =IF(D2="OVR",1,0) -> 0 | O2: =IF(ISERROR(VLOOKUP(B2,'Callsign Database'!A:F,4,0))," ",VLOOKUP(B2,'Callsign Database'!A:F,4,0)) | Q2: =IF(ISERROR(VLOOKUP(A2,'Registration Database'!A:O,15,0))," ",VLOOKUP(A2,'Registration Database'!A:O,15,0)) | R2: =IF(ISERROR(VLOOKUP(A2,'Registration Database'!A:F,6,0))," ",VLOOKUP(A2,'Registration Database'!A:F,6,0)) | S2: =IF(ISERROR(VLOOKUP(B2,'Callsign Database'!A:F,3,0)),"",VLOOKUP(B2,'Callsign Database'!A:F,3,0)) | T2: =IF(D2="loc",2)+IF(OR(D2="DEP",D2="ARR"),"1")+IF(D2="ovr","0") -> 0 | U2: =L2*2 -> 0
B3: =IF(ISERROR(VLOOKUP(A3,'Registration Database'!A:N,13,0)),"",VLOOKUP(A3,'Registration Database'!A:N,13,0)) | C3: =IF(ISERROR(VLOOKUP(A3,'Registration Database'!A:E,3,0))," ",VLOOKUP(A3,'Registration Database'!A:E,3,0)) | D3: =IF(ISNUMBER(SEARCH("UAM", B3)), "LOC", "") | E3: =IF(OR(D3="LOC", D3="OVR"), "V", "") | F3: =IF(OR(D3="DEP",D3="LOC"),"EGOW","") | H3: =IF(OR(D3="ARR",D3="LOC"),"EGOW","") | J3: =IF(ISERROR(VLOOKUP(C3,'WTC Database'!C:G,4,0))," ",VLOOKUP(C3,'WTC Database'!C:G,4,0)) | K3: =IF(ISERROR(VLOOKUP(C3,'WTC Database'!C:G,5,0))," ",VLOOKUP(C3,'WTC Database'!C:G,5,0)) | N3: =IF(D3="OVR",1,0) -> 0 | O3: =IF(ISERROR(VLOOKUP(B3,'Callsign Database'!A:F,4,0))," ",VLOOKUP(B3,'Callsign Database'!A:F,4,0)) | Q3: =IF(ISERROR(VLOOKUP(A3,'Registration Database'!A:O,15,0))," ",VLOOKUP(A3,'Registration Database'!A:O,15,0)) | R3: =IF(ISERROR(VLOOKUP(A3,'Registration Database'!A:F,6,0))," ",VLOOKUP(A3,'Registration Database'!A:F,6,0)) | S3: =IF(ISERROR(VLOOKUP(B3,'Callsign Database'!A:F,3,0)),"",VLOOKUP(B3,'Callsign Database'!A:F,3,0)) | T3: =IF(D3="loc",2)+IF(OR(D3="DEP",D3="ARR"),"1")+IF(D3="ovr","0") -> 0 | U3: =L3*2 -> 0
B4: =IF(ISERROR(VLOOKUP(A4,'Registration Database'!A:N,13,0)),"",VLOOKUP(A4,'Registration Database'!A:N,13,0)) | C4: =IF(ISERROR(VLOOKUP(A4,'Registration Database'!A:E,3,0))," ",VLOOKUP(A4,'Registration Database'!A:E,3,0)) | D4: =IF(ISNUMBER(SEARCH("UAM", B4)), "LOC", "") | E4: =IF(OR(D4="LOC", D4="OVR"), "V", "") | F4: =IF(OR(D4="DEP",D4="LOC"),"EGOW","") | H4: =IF(OR(D4="ARR",D4="LOC"),"EGOW","") | J4: =IF(ISERROR(VLOOKUP(C4,'WTC Database'!C:G,4,0))," ",VLOOKUP(C4,'WTC Database'!C:G,4,0)) | K4: =IF(ISERROR(VLOOKUP(C4,'WTC Database'!C:G,5,0))," ",VLOOKUP(C4,'WTC Database'!C:G,5,0)) | N4: =IF(D4="OVR",1,0) -> 0 | O4: =IF(ISERROR(VLOOKUP(B4,'Callsign Database'!A:F,4,0))," ",VLOOKUP(B4,'Callsign Database'!A:F,4,0)) | Q4: =IF(ISERROR(VLOOKUP(A4,'Registration Database'!A:O,15,0))," ",VLOOKUP(A4,'Registration Database'!A:O,15,0)) | R4: =IF(ISERROR(VLOOKUP(A4,'Registration Database'!A:F,6,0))," ",VLOOKUP(A4,'Registration Database'!A:F,6,0)) | S4: =IF(ISERROR(VLOOKUP(B4,'Callsign Database'!A:F,3,0)),"",VLOOKUP(B4,'Callsign Database'!A:F,3,0)) | T4: =IF(D4="loc",2)+IF(OR(D4="DEP",D4="ARR"),"1")+IF(D4="ovr","0") -> 0 | U4: =L4*2 -> 0
B5: =IF(ISERROR(VLOOKUP(A5,'Registration Database'!A:N,13,0)),"",VLOOKUP(A5,'Registration Database'!A:N,13,0)) | C5: =IF(ISERROR(VLOOKUP(A5,'Registration Database'!A:E,3,0))," ",VLOOKUP(A5,'Registration Database'!A:E,3,0)) | D5: =IF(ISNUMBER(SEARCH("UAM", B5)), "LOC", "") | E5: =IF(OR(D5="LOC", D5="OVR"), "V", "") | F5: =IF(OR(D5="DEP",D5="LOC"),"EGOW","") | H5: =IF(OR(D5="ARR",D5="LOC"),"EGOW","") | J5: =IF(ISERROR(VLOOKUP(C5,'WTC Database'!C:G,4,0))," ",VLOOKUP(C5,'WTC Database'!C:G,4,0)) | K5: =IF(ISERROR(VLOOKUP(C5,'WTC Database'!C:G,5,0))," ",VLOOKUP(C5,'WTC Database'!C:G,5,0)) | N5: =IF(D5="OVR",1,0) -> 0 | O5: =IF(ISERROR(VLOOKUP(B5,'Callsign Database'!A:F,4,0))," ",VLOOKUP(B5,'Callsign Database'!A:F,4,0)) | Q5: =IF(ISERROR(VLOOKUP(A5,'Registration Database'!A:O,15,0))," ",VLOOKUP(A5,'Registration Database'!A:O,15,0)) | R5: =IF(ISERROR(VLOOKUP(A5,'Registration Database'!A:F,6,0))," ",VLOOKUP(A5,'Registration Database'!A:F,6,0)) | S5: =IF(ISERROR(VLOOKUP(B5,'Callsign Database'!A:F,3,0)),"",VLOOKUP(B5,'Callsign Database'!A:F,3,0)) | T5: =IF(D5="loc",2)+IF(OR(D5="DEP",D5="ARR"),"1")+IF(D5="ovr","0") -> 0 | U5: =L5*2 -> 0
B6: =IF(ISERROR(VLOOKUP(A6,'Registration Database'!A:N,13,0)),"",VLOOKUP(A6,'Registration Database'!A:N,13,0)) | C6: =IF(ISERROR(VLOOKUP(A6,'Registration Database'!A:E,3,0))," ",VLOOKUP(A6,'Registration Database'!A:E,3,0)) | D6: =IF(ISNUMBER(SEARCH("UAM", B6)), "LOC", "") | E6: =IF(OR(D6="LOC", D6="OVR"), "V", "") | F6: =IF(OR(D6="DEP",D6="LOC"),"EGOW","") | H6: =IF(OR(D6="ARR",D6="LOC"),"EGOW","") | J6: =IF(ISERROR(VLOOKUP(C6,'WTC Database'!C:G,4,0))," ",VLOOKUP(C6,'WTC Database'!C:G,4,0)) | K6: =IF(ISERROR(VLOOKUP(C6,'WTC Database'!C:G,5,0))," ",VLOOKUP(C6,'WTC Database'!C:G,5,0)) | N6: =IF(D6="OVR",1,0) -> 0 | O6: =IF(ISERROR(VLOOKUP(B6,'Callsign Database'!A:F,4,0))," ",VLOOKUP(B6,'Callsign Database'!A:F,4,0)) | Q6: =IF(ISERROR(VLOOKUP(A6,'Registration Database'!A:O,15,0))," ",VLOOKUP(A6,'Registration Database'!A:O,15,0)) | R6: =IF(ISERROR(VLOOKUP(A6,'Registration Database'!A:F,6,0))," ",VLOOKUP(A6,'Registration Database'!A:F,6,0)) | S6: =IF(ISERROR(VLOOKUP(B6,'Callsign Database'!A:F,3,0)),"",VLOOKUP(B6,'Callsign Database'!A:F,3,0)) | T6: =IF(D6="loc",2)+IF(OR(D6="DEP",D6="ARR"),"1")+IF(D6="ovr","0") -> 0 | U6: =L6*2 -> 0
B7: =IF(ISERROR(VLOOKUP(A7,'Registration Database'!A:N,13,0)),"",VLOOKUP(A7,'Registration Database'!A:N,13,0)) | C7: =IF(ISERROR(VLOOKUP(A7,'Registration Database'!A:E,3,0))," ",VLOOKUP(A7,'Registration Database'!A:E,3,0)) | D7: =IF(ISNUMBER(SEARCH("UAM", B7)), "LOC", "") | E7: =IF(OR(D7="LOC", D7="OVR"), "V", "") | F7: =IF(OR(D7="DEP",D7="LOC"),"EGOW","") | H7: =IF(OR(D7="ARR",D7="LOC"),"EGOW","") | J7: =IF(ISERROR(VLOOKUP(C7,'WTC Database'!C:G,4,0))," ",VLOOKUP(C7,'WTC Database'!C:G,4,0)) | K7: =IF(ISERROR(VLOOKUP(C7,'WTC Database'!C:G,5,0))," ",VLOOKUP(C7,'WTC Database'!C:G,5,0)) | N7: =IF(D7="OVR",1,0) -> 0 | O7: =IF(ISERROR(VLOOKUP(B7,'Callsign Database'!A:F,4,0))," ",VLOOKUP(B7,'Callsign Database'!A:F,4,0)) | Q7: =IF(ISERROR(VLOOKUP(A7,'Registration Database'!A:O,15,0))," ",VLOOKUP(A7,'Registration Database'!A:O,15,0)) | R7: =IF(ISERROR(VLOOKUP(A7,'Registration Database'!A:F,6,0))," ",VLOOKUP(A7,'Registration Database'!A:F,6,0)) | S7: =IF(ISERROR(VLOOKUP(B7,'Callsign Database'!A:F,3,0)),"",VLOOKUP(B7,'Callsign Database'!A:F,3,0)) | T7: =IF(D7="loc",2)+IF(OR(D7="DEP",D7="ARR"),"1")+IF(D7="ovr","0") -> 0 | U7: =L7*2 -> 0
B8: =IF(ISERROR(VLOOKUP(A8,'Registration Database'!A:N,13,0)),"",VLOOKUP(A8,'Registration Database'!A:N,13,0)) | C8: =IF(ISERROR(VLOOKUP(A8,'Registration Database'!A:E,3,0))," ",VLOOKUP(A8,'Registration Database'!A:E,3,0)) | D8: =IF(ISNUMBER(SEARCH("UAM", B8)), "LOC", "") | E8: =IF(OR(D8="LOC", D8="OVR"), "V", "") | F8: =IF(OR(D8="DEP",D8="LOC"),"EGOW","") | H8: =IF(OR(D8="ARR",D8="LOC"),"EGOW","") | J8: =IF(ISERROR(VLOOKUP(C8,'WTC Database'!C:G,4,0))," ",VLOOKUP(C8,'WTC Database'!C:G,4,0)) | K8: =IF(ISERROR(VLOOKUP(C8,'WTC Database'!C:G,5,0))," ",VLOOKUP(C8,'WTC Database'!C:G,5,0)) | N8: =IF(D8="OVR",1,0) -> 0 | O8: =IF(ISERROR(VLOOKUP(B8,'Callsign Database'!A:F,4,0))," ",VLOOKUP(B8,'Callsign Database'!A:F,4,0)) | Q8: =IF(ISERROR(VLOOKUP(A8,'Registration Database'!A:O,15,0))," ",VLOOKUP(A8,'Registration Database'!A:O,15,0)) | R8: =IF(ISERROR(VLOOKUP(A8,'Registration Database'!A:F,6,0))," ",VLOOKUP(A8,'Registration Database'!A:F,6,0)) | S8: =IF(ISERROR(VLOOKUP(B8,'Callsign Database'!A:F,3,0)),"",VLOOKUP(B8,'Callsign Database'!A:F,3,0)) | T8: =IF(D8="loc",2)+IF(OR(D8="DEP",D8="ARR"),"1")+IF(D8="ovr","0") -> 0 | U8: =L8*2 -> 0
B9: =IF(ISERROR(VLOOKUP(A9,'Registration Database'!A:N,13,0)),"",VLOOKUP(A9,'Registration Database'!A:N,13,0)) | C9: =IF(ISERROR(VLOOKUP(A9,'Registration Database'!A:E,3,0))," ",VLOOKUP(A9,'Registration Database'!A:E,3,0)) | D9: =IF(ISNUMBER(SEARCH("UAM", B9)), "LOC", "") | E9: =IF(OR(D9="LOC", D9="OVR"), "V", "") | F9: =IF(OR(D9="DEP",D9="LOC"),"EGOW","") | H9: =IF(OR(D9="ARR",D9="LOC"),"EGOW","") | J9: =IF(ISERROR(VLOOKUP(C9,'WTC Database'!C:G,4,0))," ",VLOOKUP(C9,'WTC Database'!C:G,4,0)) | K9: =IF(ISERROR(VLOOKUP(C9,'WTC Database'!C:G,5,0))," ",VLOOKUP(C9,'WTC Database'!C:G,5,0)) | N9: =IF(D9="OVR",1,0) -> 0 | O9: =IF(ISERROR(VLOOKUP(B9,'Callsign Database'!A:F,4,0))," ",VLOOKUP(B9,'Callsign Database'!A:F,4,0)) | Q9: =IF(ISERROR(VLOOKUP(A9,'Registration Database'!A:O,15,0))," ",VLOOKUP(A9,'Registration Database'!A:O,15,0)) | R9: =IF(ISERROR(VLOOKUP(A9,'Registration Database'!A:F,6,0))," ",VLOOKUP(A9,'Registration Database'!A:F,6,0)) | S9: =IF(ISERROR(VLOOKUP(B9,'Callsign Database'!A:F,3,0)),"",VLOOKUP(B9,'Callsign Database'!A:F,3,0)) | T9: =IF(D9="loc",2)+IF(OR(D9="DEP",D9="ARR"),"1")+IF(D9="ovr","0") -> 0 | U9: =L9*2 -> 0
B10: =IF(ISERROR(VLOOKUP(A10,'Registration Database'!A:N,13,0)),"",VLOOKUP(A10,'Registration Database'!A:N,13,0)) | C10: =IF(ISERROR(VLOOKUP(A10,'Registration Database'!A:E,3,0))," ",VLOOKUP(A10,'Registration Database'!A:E,3,0)) | D10: =IF(ISNUMBER(SEARCH("UAM", B10)), "LOC", "") | E10: =IF(OR(D10="LOC", D10="OVR"), "V", "") | F10: =IF(OR(D10="DEP",D10="LOC"),"EGOW","") | H10: =IF(OR(D10="ARR",D10="LOC"),"EGOW","") | J10: =IF(ISERROR(VLOOKUP(C10,'WTC Database'!C:G,4,0))," ",VLOOKUP(C10,'WTC Database'!C:G,4,0)) | K10: =IF(ISERROR(VLOOKUP(C10,'WTC Database'!C:G,5,0))," ",VLOOKUP(C10,'WTC Database'!C:G,5,0)) | N10: =IF(D10="OVR",1,0) -> 0 | O10: =IF(ISERROR(VLOOKUP(B10,'Callsign Database'!A:F,4,0))," ",VLOOKUP(B10,'Callsign Database'!A:F,4,0)) | Q10: =IF(ISERROR(VLOOKUP(A10,'Registration Database'!A:O,15,0))," ",VLOOKUP(A10,'Registration Database'!A:O,15,0)) | R10: =IF(ISERROR(VLOOKUP(A10,'Registration Database'!A:F,6,0))," ",VLOOKUP(A10,'Registration Database'!A:F,6,0)) | S10: =IF(ISERROR(VLOOKUP(B10,'Callsign Database'!A:F,3,0)),"",VLOOKUP(B10,'Callsign Database'!A:F,3,0)) | T10: =IF(D10="loc",2)+IF(OR(D10="DEP",D10="ARR"),"1")+IF(D10="ovr","0") -> 0 | U10: =L10*2 -> 0
B11: =IF(ISERROR(VLOOKUP(A11,'Registration Database'!A:N,13,0)),"",VLOOKUP(A11,'Registration Database'!A:N,13,0)) | C11: =IF(ISERROR(VLOOKUP(A11,'Registration Database'!A:E,3,0))," ",VLOOKUP(A11,'Registration Database'!A:E,3,0)) | D11: =IF(ISNUMBER(SEARCH("UAM", B11)), "LOC", "") | E11: =IF(OR(D11="LOC", D11="OVR"), "V", "") | F11: =IF(OR(D11="DEP",D11="LOC"),"EGOW","") | H11: =IF(OR(D11="ARR",D11="LOC"),"EGOW","") | J11: =IF(ISERROR(VLOOKUP(C11,'WTC Database'!C:G,4,0))," ",VLOOKUP(C11,'WTC Database'!C:G,4,0)) | K11: =IF(ISERROR(VLOOKUP(C11,'WTC Database'!C:G,5,0))," ",VLOOKUP(C11,'WTC Database'!C:G,5,0)) | N11: =IF(D11="OVR",1,0) -> 0 | O11: =IF(ISERROR(VLOOKUP(B11,'Callsign Database'!A:F,4,0))," ",VLOOKUP(B11,'Callsign Database'!A:F,4,0)) | Q11: =IF(ISERROR(VLOOKUP(A11,'Registration Database'!A:O,15,0))," ",VLOOKUP(A11,'Registration Database'!A:O,15,0)) | R11: =IF(ISERROR(VLOOKUP(A11,'Registration Database'!A:F,6,0))," ",VLOOKUP(A11,'Registration Database'!A:F,6,0)) | S11: =IF(ISERROR(VLOOKUP(B11,'Callsign Database'!A:F,3,0)),"",VLOOKUP(B11,'Callsign Database'!A:F,3,0)) | T11: =IF(D11="loc",2)+IF(OR(D11="DEP",D11="ARR"),"1")+IF(D11="ovr","0") -> 0 | U11: =L11*2 -> 0
B12: =IF(ISERROR(VLOOKUP(A12,'Registration Database'!A:N,13,0)),"",VLOOKUP(A12,'Registration Database'!A:N,13,0)) | C12: =IF(ISERROR(VLOOKUP(A12,'Registration Database'!A:E,3,0))," ",VLOOKUP(A12,'Registration Database'!A:E,3,0)) | D12: =IF(ISNUMBER(SEARCH("UAM", B12)), "LOC", "") | E12: =IF(OR(D12="LOC", D12="OVR"), "V", "") | F12: =IF(OR(D12="DEP",D12="LOC"),"EGOW","") | H12: =IF(OR(D12="ARR",D12="LOC"),"EGOW","") | J12: =IF(ISERROR(VLOOKUP(C12,'WTC Database'!C:G,4,0))," ",VLOOKUP(C12,'WTC Database'!C:G,4,0)) | K12: =IF(ISERROR(VLOOKUP(C12,'WTC Database'!C:G,5,0))," ",VLOOKUP(C12,'WTC Database'!C:G,5,0)) | N12: =IF(D12="OVR",1,0) -> 0 | O12: =IF(ISERROR(VLOOKUP(B12,'Callsign Database'!A:F,4,0))," ",VLOOKUP(B12,'Callsign Database'!A:F,4,0)) | Q12: =IF(ISERROR(VLOOKUP(A12,'Registration Database'!A:O,15,0))," ",VLOOKUP(A12,'Registration Database'!A:O,15,0)) | R12: =IF(ISERROR(VLOOKUP(A12,'Registration Database'!A:F,6,0))," ",VLOOKUP(A12,'Registration Database'!A:F,6,0)) | S12: =IF(ISERROR(VLOOKUP(B12,'Callsign Database'!A:F,3,0)),"",VLOOKUP(B12,'Callsign Database'!A:F,3,0)) | T12: =IF(D12="loc",2)+IF(OR(D12="DEP",D12="ARR"),"1")+IF(D12="ovr","0") -> 0 | U12: =L12*2 -> 0
